Workbook
Name Slicer_Building_Age: #N/A
Name Slicer_Building_Age1: #N/A
Name Slicer_Outlier: #N/A
Name Slicer_Outlier1: #N/A
Name Slicer_Size_Bracket: #N/A
Name Slicer_Size_Bracket1: #N/A
Name Slicer_Verdict: #N/A
Name Slicer_Verdict1: #N/A
Name Slicer_Year: #N/A
Name Slicer_Year1: #N/A

Sheet Dashboard
B1: CENTRAL FLORIDA HCRE SALES REPORT | AF1: Year | AG1: (All) | AJ1: Verdict | AK1: (All) | AN1: Year | AO1: (All) | AR1: Year | AS1: (All) | AX1: Year | AY1: (All)
B2: Medical Office Building Sales | Orange, Seminole, Osceola & Lake Counties | 2020-2025 | X2: Year | Y2: (All) | AF2: County | AG2: (All) | AJ2: County | AK2: (All) | AN2: Verdict | AO2: (All) | AR2: Verdict | AS2: (All) | AX2: County | AY2: (All)
X3: Verdict | Y3: (All) | AF3: Size Bracket | AG3: (All) | AJ3: Size Bracket | AK3: (All) | AN3: Size Bracket | AO3: (All) | AR3: Size Bracket | AS3: (All) | AX3: Size Bracket | AY3: (All)
X4: Size Bracket | Y4: (All) | AF4: Building Age | AG4: (All) | AJ4: Building Age | AK4: (All) | AN4: Building Age | AO4: (All) | AR4: Building Age | AS4: (All) | AX4: Building Age | AY4: (All)
L5: AVG $/SF | N5: AVG SALE PRICE | X5: Building Age | Y5: (All) | AF5: Outlier | AG5: (Multiple Items) | AJ5: Outlier | AK5: (Multiple Items) | AN5: County | AO5: (All) | AR5: Outlier | AS5: (Multiple Items) | AX5: Outlier | AY5: (Multiple Items)
H6: =GETPIVOTDATA("Total Sales",X27) -> 195 | J6: =GETPIVOTDATA("Total Volume",X27) -> 497397799 | L6: =GETPIVOTDATA("Avg $/SF",AB27) -> 303.31751 | N6: =GETPIVOTDATA("Avg Price",AB27) -> 2550757.9 | P6: COUNTY PRICING COMPARISON | X6: Outlier | Y6: (Multiple Items) | AN6: Outlier | AO6: (Multiple Items)
H7: TOTAL SALES | J7: TOTAL VOLUME | L7: MEDIAN $/SF | N7: MEDIAN SALE PRICE | P7: County | Q7: # Sales | R7: Avg $/SF | S7: Avg Size | T7: Min Price | U7: Max Price | V7: Total Volume | AF7: Row Labels | AG7: # Sales | AJ7: Row Labels | AK7: Avg $/SF | AL7: # Sales | AR7: County | AS7: Min Price | AT7: Max Price | AU7: Avg Size | AV7: Total Volume | AX7: Verdict | AY7: Min Price | AZ7: Max Price | BA7: Avg Size | BB7: Total Volume | BC7: Avg $/SF
B8: Powered by: Lee & Associates | L8: =MEDIAN(SalesData[$/SF]) -> 252.32803 | N8: =MEDIAN(SalesData[Price]) -> 1270100 | P8: Orange | Q8: =IFERROR(GETPIVOTDATA("# Sales",$X$7,"County",P8),0) -> 68 | R8: =IFERROR(GETPIVOTDATA("Avg $/SF",$X$7,"County",P8),0) -> 313.9641 | S8: =IFERROR(GETPIVOTDATA("Avg Size",$AR$7,"County",P8),0) -> 11020.603 | T8: =IFERROR(GETPIVOTDATA("Min Price",$AR$7,"County",P8),0) -> 344600 | U8: =IFERROR(GETPIVOTDATA("Max Price",$AR$7,"County",P8),0) -> 15500000 | V8: =IFERROR(GETPIVOTDATA("Total Volume",$AR$7,"County",P8),0) -> 232837900 | X8: Row Labels | Y8: Avg $/SF | Z8: # Sales | AF8: Hospitals | AG8: 9 | AJ8: 2020 | AK8: 268.56028 | AL8: 23 | AN8: Prpty Addr | AO8: Price | AP8: $/SF | AQ8: Size | AR8: Lake | AS8: 210000 | AT8: 5272900 | AU8: 5066.4286 | AV8: 24059200 | AX8: Hospitals | AY8: 1340800 | AZ8: 15500000 | BA8: 14056 | BB8: 67023500 | BC8: 542.79918
B9: Created by: Nico Bañez | P9: Seminole | Q9: =IFERROR(GETPIVOTDATA("# Sales",$X$7,"County",P9),0) -> 53 | R9: =IFERROR(GETPIVOTDATA("Avg $/SF",$X$7,"County",P9),0) -> 245.16936 | S9: =IFERROR(GETPIVOTDATA("Avg Size",$AR$7,"County",P9),0) -> 5938.2453 | T9: =IFERROR(GETPIVOTDATA("Min Price",$AR$7,"County",P9),0) -> 250100 | U9: =IFERROR(GETPIVOTDATA("Max Price",$AR$7,"County",P9),0) -> 9998200 | V9: =IFERROR(GETPIVOTDATA("Total Volume",$AR$7,"County",P9),0) -> 78592500 | X9: Lake | Y9: 209.55388 | Z9: 21 | AF9: Medical | AG9: 125 | AJ9: 2021 | AK9: 285.97428 | AL9: 47 | AN9: 7208 Sand Lake Rd W | AO9: 15500000 | AP9: 386.9969 | AQ9: 40052 | AR9: Orange | AS9: 344600 | AT9: 15500000 | AU9: 11020.603 | AV9: 232837900 | AX9: Medical | AY9: 210000 | AZ9: 5050000 | BA9: 4442.52 | BB9: 141398100 | BC9: 253.64941
P10: Osceola | Q10: =IFERROR(GETPIVOTDATA("# Sales",$X$7,"County",P10),0) -> 23 | R10: =IFERROR(GETPIVOTDATA("Avg $/SF",$X$7,"County",P10),0) -> 291.34205 | S10: =IFERROR(GETPIVOTDATA("Avg Size",$AR$7,"County",P10),0) -> 5727 | T10: =IFERROR(GETPIVOTDATA("Min Price",$AR$7,"County",P10),0) -> 530000 | U10: =IFERROR(GETPIVOTDATA("Max Price",$AR$7,"County",P10),0) -> 5150000 | V10: =IFERROR(GETPIVOTDATA("Total Volume",$AR$7,"County",P10),0) -> 37585900 | X10: Orange | Y10: 313.9641 | Z10: 68 | AF10: Multi-Tenant Medical | AG10: 31 | AJ10: 2022 | AK10: 257.13098 | AL10: 32 | AN10: 9401 Summit Centre Wa | AO10: 15500000 | AP10: 1500.3388 | AQ10: 10331 | AR10: Osceola | AS10: 530000 | AT10: 5150000 | AU10: 5727 | AV10: 37585900 | AX10: Multi-Tenant Medical | AY10: 1600000 | AZ10: 15500000 | BA10: 20013.71 | BB10: 164653900 | BC10: 285.60207
P11: Lake | Q11: =IFERROR(GETPIVOTDATA("# Sales",$X$7,"County",P11),0) -> 21 | R11: =IFERROR(GETPIVOTDATA("Avg $/SF",$X$7,"County",P11),0) -> 209.55388 | S11: =IFERROR(GETPIVOTDATA("Avg Size",$AR$7,"County",P11),0) -> 5066.4286 | T11: =IFERROR(GETPIVOTDATA("Min Price",$AR$7,"County",P11),0) -> 210000 | U11: =IFERROR(GETPIVOTDATA("Max Price",$AR$7,"County",P11),0) -> 5272900 | V11: =IFERROR(GETPIVOTDATA("Total Volume",$AR$7,"County",P11),0) -> 24059200 | X11: Osceola | Y11: 291.34205 | Z11: 23 | AJ11: 2023 | AK11: 249.3862 | AL11: 26 | AN11: 7009 Dr Phillips Bl | AO11: 15000000 | AP11: 634.16903 | AQ11: 23653 | AR11: Seminole | AS11: 250100 | AT11: 9998200 | AU11: 5938.2453 | AV11: 78592500
X12: Seminole | Y12: 245.16936 | Z12: 53 | AJ12: 2024 | AK12: 263.12592 | AL12: 20 | AN12: 1745 Mills Av N | AO12: 13200000 | AP12: 470.42053 | AQ12: 28060
AJ13: 2025 | AK13: 344.27083 | AL13: 17 | AN13: 2909 Orange Av N | AO13: 10221900 | AP13: 651.90689 | AQ13: 15680
AN14: 658 Oviedo Medical Dr | AO14: 9998200 | AP14: 587.19681 | AQ14: 17027
P15: CATEGORY BREAKDOWN | AN15: 100 Sybelia Av E | AO15: 7750000 | AP15: 179.94799 | AQ15: 43068
H16: $/SF RANGE | J16: SALE PRICE RANGE | P16: Category | Q16: # Sales | R16: Avg $/SF | S16: Avg Size | T16: Min Price | U16: Max Price | V16: Total Volume | AN16: 12200 Colonial Dr W | AO16: 7600000 | AP16: 246.90556 | AQ16: 30781
H17: ="$"&TEXT(GETPIVOTDATA("Min $/SF",AB27),"#,##0")&" – $"&TEXT(GETPIVOTDATA("Max $/SF",AB27),"#,##0") -> $45 – $1,500 | J17: =TEXT(GETPIVOTDATA("Min Price",AB27),IF(GETPIVOTDATA("Min Price",AB27)>=1000000,"$#,##0,,""M""","$#,##0,""K"""))&" – "&TEXT(GETPIVOTDATA("Max Price",AB27),IF(GETPIVOTDATA("Max Price",AB27)>=1000000,"$#,##0,,""M""","$#,##0,""K""")) -> $210K – $33M | P17: Medical | Q17: =IFERROR(GETPIVOTDATA("# Sales",$AF$7,"Verdict",P17),0) -> 125 | R17: =IFERROR(GETPIVOTDATA("Avg $/SF",$AX$7,"Verdict",P17),0) -> 253.64941 | S17: =IFERROR(GETPIVOTDATA("Avg Size",$AX$7,"Verdict",P17),0) -> 4442.52 | T17: =IFERROR(GETPIVOTDATA("Min Price",$AX$7,"Verdict",P17),0) -> 210000 | U17: =IFERROR(GETPIVOTDATA("Max Price",$AX$7,"Verdict",P17),0) -> 5050000 | V17: =IFERROR(GETPIVOTDATA("Total Volume",$AX$7,"Verdict",P17),0) -> 141398100 | AN17: 7232 Sand Lake Rd W | AO17: 7500000 | AP17: 441.82622 | AQ17: 16975
P18: Multi-Tenant Medical | Q18: =IFERROR(GETPIVOTDATA("# Sales",$AF$7,"Verdict",P18),0) -> 31 | R18: =IFERROR(GETPIVOTDATA("Avg $/SF",$AX$7,"Verdict",P18),0) -> 285.60207 | S18: =IFERROR(GETPIVOTDATA("Avg Size",$AX$7,"Verdict",P18),0) -> 20013.71 | T18: =IFERROR(GETPIVOTDATA("Min Price",$AX$7,"Verdict",P18),0) -> 1600000 | U18: =IFERROR(GETPIVOTDATA("Max Price",$AX$7,"Verdict",P18),0) -> 15500000 | V18: =IFERROR(GETPIVOTDATA("Total Volume",$AX$7,"Verdict",P18),0) -> 164653900 | AN18: 1505 Colonial Dr E | AO18: 7125000 | AP18: 184.85847 | AQ18: 38543
P19: Hospitals | Q19: =IFERROR(GETPIVOTDATA("# Sales",$AF$7,"Verdict",P19),0) -> 9 | R19: =IFERROR(GETPIVOTDATA("Avg $/SF",$AX$7,"Verdict",P19),0) -> 542.79918 | S19: =IFERROR(GETPIVOTDATA("Avg Size",$AX$7,"Verdict",P19),0) -> 14056 | T19: =IFERROR(GETPIVOTDATA("Min Price",$AX$7,"Verdict",P19),0) -> 1340800 | U19: =IFERROR(GETPIVOTDATA("Max Price",$AX$7,"Verdict",P19),0) -> 15500000 | V19: =IFERROR(GETPIVOTDATA("Total Volume",$AX$7,"Verdict",P19),0) -> 67023500 | AN19: 1511 SR 434 # 1001 E | AO19: 7000000 | AP19: 176.76768 | AQ19: 39600
X20: Year | Y20: (All) | AN20: 341 Maitland Av N | AO20: 7000000 | AP20: 152.45894 | AQ20: 45914
X21: Verdict | Y21: (All) | AN21: 954 Orlando Av S | AO21: 6349400 | AP21: 424 | AQ21: 14975
X22: County | Y22: (All) | AN22: 1781 Park Center Dr | AO22: 5913600 | AP22: 238.42277 | AQ22: 24803
X23: Size Bracket | Y23: (All) | AN23: 770 Concourse Pk | AO23: 5610000 | AP23: 395.90685 | AQ23: 14170
X24: Building Age | Y24: (All) | AN24: 1701 Park Center Dr | AO24: 5600000 | AP24: 171.09163 | AQ24: 32731
P25: TOP SALES | X25: Outlier | Y25: (All) | AN25: 600 North Blvd W | AO25: 5272900 | AP25: 263.645 | AQ25: 20000
P26: Address | Q26: County | R26: Price | S26: Size | T26: $/SF | U26: Category | V26: Tenant | AN26: 3480 Polynesian Isle Blvd | AO26: 5150000 | AP26: 412.66026 | AQ26: 12480
P27: =AN9 -> 7208 Sand Lake Rd W | Q27: =INDEX(SalesData[County],MATCH(P27,SalesData[Prpty Addr],0)) -> Orange | R27: =AO9 -> 15500000 | S27: =AQ9 -> 40052 | T27: =AP9 -> 386.9969 | U27: =INDEX(SalesData[Verdict],MATCH(P27,SalesData[Prpty Addr],0)) -> Multi-Tenant Medical | V27: =INDEX(SalesData[Current Tenant],MATCH(P27,SalesData[Prpty Addr],0)) -> 7208 Sand Lake - Office Complex | X27: Total Volume | Y27: Avg $/SF | Z27: Avg Price | AA27: Min Price | AB27: Max Price | AC27: Min $/SF | AD27: Max $/SF | AE27: Avg Size | AF27: Total Sales | AN27: 780 Concourse Pk | AO27: 5100000 | AP27: 389.31298 | AQ27: 13100
P28: =AN10 -> 9401 Summit Centre Wa | Q28: =INDEX(SalesData[County],MATCH(P28,SalesData[Prpty Addr],0)) -> Orange | R28: =AO10 -> 15500000 | S28: =AQ10 -> 10331 | T28: =AP10 -> 1500.3388 | U28: =INDEX(SalesData[Verdict],MATCH(P28,SalesData[Prpty Addr],0)) -> Hospitals | V28: =INDEX(SalesData[Current Tenant],MATCH(P28,SalesData[Prpty Addr],0)) -> **HCA Florida Maitland Emergency (Freestanding ER)** MEDICAL CENTER | X28: 497397799 | Y28: 303.31751 | Z28: 2550757.9 | AA28: 210000 | AB28: 33444697 | AC28: 45.304778 | AD28: 1500.3388 | AE28: 8917.5641 | AF28: 195 | AN28: 106 Boston # 100 Ave | AO28: 5050000 | AP28: 202.46161 | AQ28: 24943
P29: =AN11 -> 7009 Dr Phillips Bl | Q29: =INDEX(SalesData[County],MATCH(P29,SalesData[Prpty Addr],0)) -> Orange | R29: =AO11 -> 15000000 | S29: =AQ11 -> 23653 | T29: =AP11 -> 634.16903 | U29: =INDEX(SalesData[Verdict],MATCH(P29,SalesData[Prpty Addr],0)) -> Multi-Tenant Medical | V29: =INDEX(SalesData[Current Tenant],MATCH(P29,SalesData[Prpty Addr],0)) -> Belmart LLC Dr Phillips | AN29: 1605 Fairbanks Av W | AO29: 5000000 | AP29: 405.28492 | AQ29: 12337
P30: =AN12 -> 1745 Mills Av N | Q30: =INDEX(SalesData[County],MATCH(P30,SalesData[Prpty Addr],0)) -> Orange | R30: =AO12 -> 13200000 | S30: =AQ12 -> 28060 | T30: =AP12 -> 470.42053 | U30: =INDEX(SalesData[Verdict],MATCH(P30,SalesData[Prpty Addr],0)) -> Hospitals | V30: =INDEX(SalesData[Current Tenant],MATCH(P30,SalesData[Prpty Addr],0)) -> Central Florida Cardiology Group MEDICAL CENTER | AN30: 10131 Colonial Dr W | AO30: 4918100 | AP30: 281.58136 | AQ30: 17466
AN31: 1803 Park Center Dr | AO31: 4875000 | AP31: 221.49023 | AQ31: 22010
AN32: 1071 Sun Dr S | AO32: 4500000 | AP32: 247.25275 | AQ32: 18200
AN33: 2233 Lee Rd | AO33: 4216800 | AP33: 200.81913 | AQ33: 20998
AN34: 100 Waymont Ct | AO34: 4100000 | AP34: 227.77778 | AQ34: 18000
AN35: 2940 Maguire Rd | AO35: 4030000 | AP35: 494.5999 | AQ35: 8148
AN36: 1400 Orlando Av S | AO36: 3900000 | AP36: 185.51111 | AQ36: 21023
AN37: 750 Concourse Pk | AO37: 3570000 | AP37: 399.41821 | AQ37: 8938
AN38: 1000 E Irlo Bronson Memorial | AO38: 3552600 | AP38: 466.95584 | AQ38: 7608
AN39: 1301 Colonial Dr W | AO39: 3518200 | AP39: 396.64036 | AQ39: 8870
AN40: 788 Montgomery Av | AO40: 3499900 | AP40: 251.91823 | AQ40: 13893
...

Sheet Market Trends
A1: CENTRAL FLORIDA HEALTHCARE REAL ESTATE — MARKET TRENDS (2020–2025)
A3: 1. INTEREST RATE ENVIRONMENT
B5: 2020 | C5: 2021 | D5: 2022 | E5: 2023 | F5: 2024 | G5: 2025 YTD
A6: Fed Funds Rate (Avg %) | B6: 0.0036 | C6: 0.0008 | D6: 0.0168 | E6: 0.0503 | F6: 0.0458 | G6: 0.0398
A7: 10-Year Treasury (Avg %) | B7: 0.0089 | C7: 0.0145 | D7: 0.0295 | E7: 0.0396 | F7: 0.0425 | G7: 0.0425
A10: 2. POPULATION GROWTH BY COUNTY
B12: 2020 | C12: 2021 | D12: 2022 | E12: 2023 | F12: 2024 | G12: 2025 Est.
A13: Orange County | B13: 1429908 | C13: 1458500 | D13: 1481321 | E13: 1492951 | F13: 1511568 | G13: 1536045
A14: Seminole County | B14: 470856 | C14: 473500 | D14: 476200 | E14: 478800 | F14: 481470 | G14: 484200
A15: Osceola County | B15: 388656 | C15: 406540 | D15: 424946 | E15: 439225 | F15: 451231 | G15: 484915
A16: Lake County | B16: 383956 | C16: 393600 | D16: 410090 | E16: 424462 | F16: 432000 | G16: 425000
A17: 4-County Total | B17: =SUM(B13:B16) -> 2673376 | C17: =SUM(C13:C16) -> 2732140 | D17: =SUM(D13:D16) -> 2792557 | E17: =SUM(E13:E16) -> 2835438 | F17: =SUM(F13:F16) -> 2876269 | G17: =SUM(G13:G16) -> 2930160
A19: Orange YoY Growth | C19: =(C13-B13)/B13 -> 0.019995692 | D19: =(D13-C13)/C13 -> 0.015646897 | E19: =(E13-D13)/D13 -> 0.0078511005 | F19: =(F13-E13)/E13 -> 0.012469934 | G19: =(G13-F13)/F13 -> 0.016193119
A20: Seminole YoY Growth | C20: =(C14-B14)/B14 -> 0.0056153049 | D20: =(D14-C14)/C14 -> 0.0057022175 | E20: =(E14-D14)/D14 -> 0.0054598908 | F20: =(F14-E14)/E14 -> 0.0055764411 | G20: =(G14-F14)/F14 -> 0.0056701352
A21: Osceola YoY Growth | C21: =(C15-B15)/B15 -> 0.046014985 | D21: =(D15-C15)/C15 -> 0.045274758 | E21: =(E15-D15)/D15 -> 0.033601916 | F21: =(F15-E15)/E15 -> 0.02733451 | G21: =(G15-F15)/F15 -> 0.074649127
A22: Lake YoY Growth | C22: =(C16-B16)/B16 -> 0.025117461 | D22: =(D16-C16)/C16 -> 0.041895325 | E22: =(E16-D16)/D16 -> 0.035045966 | F22: =(F16-E16)/E16 -> 0.017758951 | G22: =(G16-F16)/F16 -> -0.016203704
A25: 3. MEDICAL OFFICE CONSTRUCTION COSTS
B27: 2020 | C27: 2021 | D27: 2022 | E27: 2023 | F27: 2024 | G27: 2025
A28: Construction Cost ($/SF) | B28: N/A | C28: N/A | D28: N/A | E28: N/A | F28: N/A | G28: N/A
A29: ⚠️ Data behind paywall — requires RSMeans, Gordian, or Cumming construction cost reports. Enter your data above.
A32: 4. HEALTHCARE REAL ESTATE CAP RATES
B34: 2020 | C34: 2021 | D34: 2022 | E34: 2023 | F34: 2024 | G34: 2025
A35: Medical Office Cap Rate (%) | B35: N/A | C35: N/A | D35: N/A | E35: N/A | F35: N/A | G35: N/A
A36: ⚠️ Data behind paywall — requires CBRE, JLL, or RCA cap rate surveys. Enter your data above.
A38: SOURCES & REFERENCES
A39: Interest Rate Data
A40: Board of Governors of the Federal Reserve System. "Federal Funds Effective Rate [FEDFUNDS]." FRED, Federal Reserve Bank of St. Louis. Retrieved April 2025. https://fred.stlouisfed.org/series/FEDFUNDS
A41: Board of Governors of the Federal Reserve System. "Market Yield on U.S. Treasury Securities at 10-Year Constant Maturity [DGS10]." FRED, Federal Reserve Bank of St. Louis. Retrieved April 2025. https://fred.stlouisfed.org/series/DGS10
A43: Population Data
A44: Florida Legislature, Office of Economic & Demographic Research (EDR). "County Area Profiles: Orange County, Osceola County." Retrieved April 2025. https://edr.state.fl.us/content/area-profiles/
A45: U.S. Census Bureau. "QuickFacts: Seminole County, FL; Lake County, FL." Retrieved April 2025. https://www.census.gov/quickfacts/
A46: Florida-Demographics.com. "Seminole County Demographics." Census-derived population estimates. Retrieved April 2025. https://www.florida-demographics.com/seminole-county-demographics
A47: MSA Population Comparison Data
A48: U.S. Census Bureau. "Annual Estimates of the Resident Population for Metropolitan Statistical Areas." Vintage 2024. Retrieved via FRED, Federal Reserve Bank of St. Louis, April 2025. Series: ORLPOP, DFWPOP, CGRPOP, SATPOP, TMAPOP, NVLPOP, PHXPOP, MIMPOP. https://fred.stlouisfed.org/release?rid=111
A50: Construction Cost & Cap Rate Data (Not Yet Populated)
... A54: Interest rates reflect annual averages of daily observations; 2025 figures represent January–April year-to-date averages. Population estimates for Seminole County (2021–2023) and Lake County (2021–2023) are linear interpolations between U.S. Census 2020 decennial counts and the latest available annual estimate. MSA population estimates are July 1 estimates from the Census Bureau's Vintage 2024 series. All other population figures are sourced directly from FL EDR or U.S. Census Bureau releases.
A56: Report prepared using data retrieved April 2025. All figures are subject to revision upon release of updated government estimates. | B56: =C12 -> 2021 | C56: =D12 -> 2022 | D56: =E12 -> 2023 | E56: =F12 -> 2024 | F56: =G12 -> 2025 Est.
A57: Orange County | B57: =C19 -> 0.019995692 | C57: =D19 -> 0.015646897 | D57: =E19 -> 0.0078511005 | E57: =F19 -> 0.012469934 | F57: =G19 -> 0.016193119
A58: Seminole County | B58: =C20 -> 0.0056153049 | C58: =D20 -> 0.0057022175 | D58: =E20 -> 0.0054598908 | E58: =F20 -> 0.0055764411 | F58: =G20 -> 0.0056701352
A59: Osceola County | B59: =C21 -> 0.046014985 | C59: =D21 -> 0.045274758 | D59: =E21 -> 0.033601916 | E59: =F21 -> 0.02733451 | F59: =G21 -> 0.074649127
...

Sheet Copy Dashboard
B1: CENTRAL FLORIDA HCRE SALES REPORT | AF1: Year | AG1: (All) | AJ1: Verdict | AK1: (All) | AN1: Year | AO1: (All) | AR1: Year | AS1: (All) | AX1: Year | AY1: (All)
B2: Medical Office Building Sales | Orange, Seminole, Osceola & Lake Counties | 2020-2025 | X2: Year | Y2: (All) | AF2: County | AG2: (All) | AJ2: County | AK2: (All) | AN2: Verdict | AO2: (All) | AR2: Verdict | AS2: (All) | AX2: County | AY2: (All)
X3: Verdict | Y3: (All) | AF3: Size Bracket | AG3: (All) | AJ3: Size Bracket | AK3: (All) | AN3: Size Bracket | AO3: (All) | AR3: Size Bracket | AS3: (All) | AX3: Size Bracket | AY3: (All)
X4: Size Bracket | Y4: (All) | AF4: Building Age | AG4: (All) | AJ4: Building Age | AK4: (All) | AN4: Building Age | AO4: (All) | AR4: Building Age | AS4: (All) | AX4: Building Age | AY4: (All)
L5: AVG $/SF | N5: AVG SALE PRICE | X5: Building Age | Y5: (All) | AF5: Outlier | AG5: (Multiple Items) | AJ5: Outlier | AK5: (Multiple Items) | AN5: County | AO5: (All) | AR5: Outlier | AS5: (Multiple Items) | AX5: Outlier | AY5: (Multiple Items)
H6: =GETPIVOTDATA("Total Sales",X27) -> 195 | J6: =GETPIVOTDATA("Total Volume",X27) -> 497397799 | L6: =GETPIVOTDATA("Avg $/SF",AB27) -> 303.31751 | N6: =GETPIVOTDATA("Avg Price",AB27) -> 2550757.9 | P6: COUNTY PRICING COMPARISON | X6: Outlier | Y6: (Multiple Items) | AN6: Outlier | AO6: (Multiple Items)
H7: TOTAL SALES | J7: TOTAL VOLUME | L7: MEDIAN $/SF | N7: MEDIAN SALE PRICE | P7: County | Q7: # Sales | R7: Avg $/SF | S7: Avg Size | T7: Min Price | U7: Max Price | V7: Total Volume | AF7: Row Labels | AG7: # Sales | AJ7: Row Labels | AK7: Avg $/SF | AL7: # Sales | AR7: County | AS7: Min Price | AT7: Max Price | AU7: Avg Size | AV7: Total Volume | AX7: Verdict | AY7: Min Price | AZ7: Max Price | BA7: Avg Size | BB7: Total Volume | BC7: Avg $/SF
B8: Powered by: Lee & Associates | L8: =MEDIAN(SalesData[$/SF]) -> 252.32803 | N8: =MEDIAN(SalesData[Price]) -> 1270100 | P8: Orange | Q8: =IFERROR(GETPIVOTDATA("# Sales",$X$7,"County",P8),0) -> 68 | R8: =IFERROR(GETPIVOTDATA("Avg $/SF",$X$7,"County",P8),0) -> 313.9641 | S8: =IFERROR(GETPIVOTDATA("Avg Size",$AR$7,"County",P8),0) -> 11020.603 | T8: =IFERROR(GETPIVOTDATA("Min Price",$AR$7,"County",P8),0) -> 344600 | U8: =IFERROR(GETPIVOTDATA("Max Price",$AR$7,"County",P8),0) -> 15500000 | V8: =IFERROR(GETPIVOTDATA("Total Volume",$AR$7,"County",P8),0) -> 232837900 | X8: Row Labels | Y8: Avg $/SF | Z8: # Sales | AF8: Hospitals | AG8: 9 | AJ8: 2020 | AK8: 268.56028 | AL8: 23 | AN8: Prpty Addr | AO8: Price | AP8: $/SF | AQ8: Size | AR8: Lake | AS8: 210000 | AT8: 5272900 | AU8: 5066.4286 | AV8: 24059200 | AX8: Hospitals | AY8: 1340800 | AZ8: 15500000 | BA8: 14056 | BB8: 67023500 | BC8: 542.79918
B9: Created by: Nico Bañez | P9: Seminole | Q9: =IFERROR(GETPIVOTDATA("# Sales",$X$7,"County",P9),0) -> 53 | R9: =IFERROR(GETPIVOTDATA("Avg $/SF",$X$7,"County",P9),0) -> 245.16936 | S9: =IFERROR(GETPIVOTDATA("Avg Size",$AR$7,"County",P9),0) -> 5938.2453 | T9: =IFERROR(GETPIVOTDATA("Min Price",$AR$7,"County",P9),0) -> 250100 | U9: =IFERROR(GETPIVOTDATA("Max Price",$AR$7,"County",P9),0) -> 9998200 | V9: =IFERROR(GETPIVOTDATA("Total Volume",$AR$7,"County",P9),0) -> 78592500 | X9: Lake | Y9: 209.55388 | Z9: 21 | AF9: Medical | AG9: 125 | AJ9: 2021 | AK9: 285.97428 | AL9: 47 | AN9: 7208 Sand Lake Rd W | AO9: 15500000 | AP9: 386.9969 | AQ9: 40052 | AR9: Orange | AS9: 344600 | AT9: 15500000 | AU9: 11020.603 | AV9: 232837900 | AX9: Medical | AY9: 210000 | AZ9: 5050000 | BA9: 4442.52 | BB9: 141398100 | BC9: 253.64941
P10: Osceola | Q10: =IFERROR(GETPIVOTDATA("# Sales",$X$7,"County",P10),0) -> 23 | R10: =IFERROR(GETPIVOTDATA("Avg $/SF",$X$7,"County",P10),0) -> 291.34205 | S10: =IFERROR(GETPIVOTDATA("Avg Size",$AR$7,"County",P10),0) -> 5727 | T10: =IFERROR(GETPIVOTDATA("Min Price",$AR$7,"County",P10),0) -> 530000 | U10: =IFERROR(GETPIVOTDATA("Max Price",$AR$7,"County",P10),0) -> 5150000 | V10: =IFERROR(GETPIVOTDATA("Total Volume",$AR$7,"County",P10),0) -> 37585900 | X10: Orange | Y10: 313.9641 | Z10: 68 | AF10: Multi-Tenant Medical | AG10: 31 | AJ10: 2022 | AK10: 257.13098 | AL10: 32 | AN10: 9401 Summit Centre Wa | AO10: 15500000 | AP10: 1500.3388 | AQ10: 10331 | AR10: Osceola | AS10: 530000 | AT10: 5150000 | AU10: 5727 | AV10: 37585900 | AX10: Multi-Tenant Medical | AY10: 1600000 | AZ10: 15500000 | BA10: 20013.71 | BB10: 164653900 | BC10: 285.60207
P11: Lake | Q11: =IFERROR(GETPIVOTDATA("# Sales",$X$7,"County",P11),0) -> 21 | R11: =IFERROR(GETPIVOTDATA("Avg $/SF",$X$7,"County",P11),0) -> 209.55388 | S11: =IFERROR(GETPIVOTDATA("Avg Size",$AR$7,"County",P11),0) -> 5066.4286 | T11: =IFERROR(GETPIVOTDATA("Min Price",$AR$7,"County",P11),0) -> 210000 | U11: =IFERROR(GETPIVOTDATA("Max Price",$AR$7,"County",P11),0) -> 5272900 | V11: =IFERROR(GETPIVOTDATA("Total Volume",$AR$7,"County",P11),0) -> 24059200 | X11: Osceola | Y11: 291.34205 | Z11: 23 | AJ11: 2023 | AK11: 249.3862 | AL11: 26 | AN11: 7009 Dr Phillips Bl | AO11: 15000000 | AP11: 634.16903 | AQ11: 23653 | AR11: Seminole | AS11: 250100 | AT11: 9998200 | AU11: 5938.2453 | AV11: 78592500
X12: Seminole | Y12: 245.16936 | Z12: 53 | AJ12: 2024 | AK12: 263.12592 | AL12: 20 | AN12: 1745 Mills Av N | AO12: 13200000 | AP12: 470.42053 | AQ12: 28060
AJ13: 2025 | AK13: 344.27083 | AL13: 17 | AN13: 2909 Orange Av N | AO13: 10221900 | AP13: 651.90689 | AQ13: 15680
AN14: 658 Oviedo Medical Dr | AO14: 9998200 | AP14: 587.19681 | AQ14: 17027
P15: CATEGORY BREAKDOWN | AN15: 100 Sybelia Av E | AO15: 7750000 | AP15: 179.94799 | AQ15: 43068
H16: $/SF RANGE | J16: SALE PRICE RANGE | P16: Category | Q16: # Sales | R16: Avg $/SF | S16: Avg Size | T16: Min Price | U16: Max Price | V16: Total Volume | AN16: 12200 Colonial Dr W | AO16: 7600000 | AP16: 246.90556 | AQ16: 30781
H17: ="$"&TEXT(GETPIVOTDATA("Min $/SF",AB27),"#,##0")&" – $"&TEXT(GETPIVOTDATA("Max $/SF",AB27),"#,##0") -> $45 – $1,500 | J17: =TEXT(GETPIVOTDATA("Min Price",AB27),IF(GETPIVOTDATA("Min Price",AB27)>=1000000,"$#,##0,,""M""","$#,##0,""K"""))&" – "&TEXT(GETPIVOTDATA("Max Price",AB27),IF(GETPIVOTDATA("Max Price",AB27)>=1000000,"$#,##0,,""M""","$#,##0,""K""")) -> $210K – $33M | P17: Medical | Q17: =IFERROR(GETPIVOTDATA("# Sales",$AF$7,"Verdict",P17),0) -> 125 | R17: =IFERROR(GETPIVOTDATA("Avg $/SF",$AX$7,"Verdict",P17),0) -> 253.64941 | S17: =IFERROR(GETPIVOTDATA("Avg Size",$AX$7,"Verdict",P17),0) -> 4442.52 | T17: =IFERROR(GETPIVOTDATA("Min Price",$AX$7,"Verdict",P17),0) -> 210000 | U17: =IFERROR(GETPIVOTDATA("Max Price",$AX$7,"Verdict",P17),0) -> 5050000 | V17: =IFERROR(GETPIVOTDATA("Total Volume",$AX$7,"Verdict",P17),0) -> 141398100 | AN17: 7232 Sand Lake Rd W | AO17: 7500000 | AP17: 441.82622 | AQ17: 16975
P18: Multi-Tenant Medical | Q18: =IFERROR(GETPIVOTDATA("# Sales",$AF$7,"Verdict",P18),0) -> 31 | R18: =IFERROR(GETPIVOTDATA("Avg $/SF",$AX$7,"Verdict",P18),0) -> 285.60207 | S18: =IFERROR(GETPIVOTDATA("Avg Size",$AX$7,"Verdict",P18),0) -> 20013.71 | T18: =IFERROR(GETPIVOTDATA("Min Price",$AX$7,"Verdict",P18),0) -> 1600000 | U18: =IFERROR(GETPIVOTDATA("Max Price",$AX$7,"Verdict",P18),0) -> 15500000 | V18: =IFERROR(GETPIVOTDATA("Total Volume",$AX$7,"Verdict",P18),0) -> 164653900 | AN18: 1505 Colonial Dr E | AO18: 7125000 | AP18: 184.85847 | AQ18: 38543
P19: Hospitals | Q19: =IFERROR(GETPIVOTDATA("# Sales",$AF$7,"Verdict",P19),0) -> 9 | R19: =IFERROR(GETPIVOTDATA("Avg $/SF",$AX$7,"Verdict",P19),0) -> 542.79918 | S19: =IFERROR(GETPIVOTDATA("Avg Size",$AX$7,"Verdict",P19),0) -> 14056 | T19: =IFERROR(GETPIVOTDATA("Min Price",$AX$7,"Verdict",P19),0) -> 1340800 | U19: =IFERROR(GETPIVOTDATA("Max Price",$AX$7,"Verdict",P19),0) -> 15500000 | V19: =IFERROR(GETPIVOTDATA("Total Volume",$AX$7,"Verdict",P19),0) -> 67023500 | AN19: 1511 SR 434 # 1001 E | AO19: 7000000 | AP19: 176.76768 | AQ19: 39600
X20: Year | Y20: (All) | AN20: 341 Maitland Av N | AO20: 7000000 | AP20: 152.45894 | AQ20: 45914
X21: Verdict | Y21: (All) | AN21: 954 Orlando Av S | AO21: 6349400 | AP21: 424 | AQ21: 14975
X22: County | Y22: (All) | AN22: 1781 Park Center Dr | AO22: 5913600 | AP22: 238.42277 | AQ22: 24803
X23: Size Bracket | Y23: (All) | AN23: 770 Concourse Pk | AO23: 5610000 | AP23: 395.90685 | AQ23: 14170
X24: Building Age | Y24: (All) | AN24: 1701 Park Center Dr | AO24: 5600000 | AP24: 171.09163 | AQ24: 32731
P25: TOP SALES | X25: Outlier | Y25: (All) | AN25: 600 North Blvd W | AO25: 5272900 | AP25: 263.645 | AQ25: 20000
P26: Address | Q26: County | R26: Price | S26: Size | T26: $/SF | U26: Category | V26: Tenant | AN26: 3480 Polynesian Isle Blvd | AO26: 5150000 | AP26: 412.66026 | AQ26: 12480
P27: =AN9 -> 7208 Sand Lake Rd W | Q27: =INDEX(SalesData[County],MATCH(P27,SalesData[Prpty Addr],0)) -> Orange | R27: =AO9 -> 15500000 | S27: =AQ9 -> 40052 | T27: =AP9 -> 386.9969 | U27: =INDEX(SalesData[Verdict],MATCH(P27,SalesData[Prpty Addr],0)) -> Multi-Tenant Medical | V27: =INDEX(SalesData[Current Tenant],MATCH(P27,SalesData[Prpty Addr],0)) -> 7208 Sand Lake - Office Complex | X27: Total Volume | Y27: Avg $/SF | Z27: Avg Price | AA27: Min Price | AB27: Max Price | AC27: Min $/SF | AD27: Max $/SF | AE27: Avg Size | AF27: Total Sales | AN27: 780 Concourse Pk | AO27: 5100000 | AP27: 389.31298 | AQ27: 13100
P28: =AN10 -> 9401 Summit Centre Wa | Q28: =INDEX(SalesData[County],MATCH(P28,SalesData[Prpty Addr],0)) -> Orange | R28: =AO10 -> 15500000 | S28: =AQ10 -> 10331 | T28: =AP10 -> 1500.3388 | U28: =INDEX(SalesData[Verdict],MATCH(P28,SalesData[Prpty Addr],0)) -> Hospitals | V28: =INDEX(SalesData[Current Tenant],MATCH(P28,SalesData[Prpty Addr],0)) -> **HCA Florida Maitland Emergency (Freestanding ER)** MEDICAL CENTER | X28: 497397799 | Y28: 303.31751 | Z28: 2550757.9 | AA28: 210000 | AB28: 33444697 | AC28: 45.304778 | AD28: 1500.3388 | AE28: 8917.5641 | AF28: 195 | AN28: 106 Boston # 100 Ave | AO28: 5050000 | AP28: 202.46161 | AQ28: 24943
P29: =AN11 -> 7009 Dr Phillips Bl | Q29: =INDEX(SalesData[County],MATCH(P29,SalesData[Prpty Addr],0)) -> Orange | R29: =AO11 -> 15000000 | S29: =AQ11 -> 23653 | T29: =AP11 -> 634.16903 | U29: =INDEX(SalesData[Verdict],MATCH(P29,SalesData[Prpty Addr],0)) -> Multi-Tenant Medical | V29: =INDEX(SalesData[Current Tenant],MATCH(P29,SalesData[Prpty Addr],0)) -> Belmart LLC Dr Phillips | AN29: 1605 Fairbanks Av W | AO29: 5000000 | AP29: 405.28492 | AQ29: 12337
P30: =AN12 -> 1745 Mills Av N | Q30: =INDEX(SalesData[County],MATCH(P30,SalesData[Prpty Addr],0)) -> Orange | R30: =AO12 -> 13200000 | S30: =AQ12 -> 28060 | T30: =AP12 -> 470.42053 | U30: =INDEX(SalesData[Verdict],MATCH(P30,SalesData[Prpty Addr],0)) -> Hospitals | V30: =INDEX(SalesData[Current Tenant],MATCH(P30,SalesData[Prpty Addr],0)) -> Central Florida Cardiology Group MEDICAL CENTER | AN30: 10131 Colonial Dr W | AO30: 4918100 | AP30: 281.58136 | AQ30: 17466
AN31: 1803 Park Center Dr | AO31: 4875000 | AP31: 221.49023 | AQ31: 22010
AN32: 1071 Sun Dr S | AO32: 4500000 | AP32: 247.25275 | AQ32: 18200
AN33: 2233 Lee Rd | AO33: 4216800 | AP33: 200.81913 | AQ33: 20998
AN34: 100 Waymont Ct | AO34: 4100000 | AP34: 227.77778 | AQ34: 18000
AN35: 2940 Maguire Rd | AO35: 4030000 | AP35: 494.5999 | AQ35: 8148
AN36: 1400 Orlando Av S | AO36: 3900000 | AP36: 185.51111 | AQ36: 21023
AN37: 750 Concourse Pk | AO37: 3570000 | AP37: 399.41821 | AQ37: 8938
AN38: 1000 E Irlo Bronson Memorial | AO38: 3552600 | AP38: 466.95584 | AQ38: 7608
AN39: 1301 Colonial Dr W | AO39: 3518200 | AP39: 396.64036 | AQ39: 8870
AN40: 788 Montgomery Av | AO40: 3499900 | AP40: 251.91823 | AQ40: 13893
...

Sheet Master
A1: *2020 to 2025 Office Sales Data - Sorted via Google Gemini and Claude. Manual sorting via Nico Bañez.
A2: VERIFIED VIA HUMAN (1-3 GRADE) | B2: Prpty Addr | C2: County | D2: Date Trnsfr | E2: Price | F2: $/SF | G2: Tot Ht Area | H2: Total Area | I2: Grantee | J2: Yr Built 1 | K2: Use Code | L2: Zoning | M2: Parcel ID | N2: Verdict | O2: Confidence | P2: Current Tenant | Q2: Evidence Link | R2: Google Map Link | S2: Evidence P2. | T2: Outlier? | U2: Reason | V2: Appraiser Link
A3: 3 | B3: 1049 Willa Springs Dr | C3: Seminole | D3: 2021/07 | E3: 2285000 | F3: =Table2[[#This Row],[Price]]/Table2[[#This Row],[Tot Ht Area]] -> 223.58121 | G3: 10220 | H3: 10220 | I3: 1049 Willa Springs LLC | J3: 2004 | K3: 19 | M3: 2130 24 508 0000 0060 | N3: Multi-Tenant Medical | O3: High | P3: Winter Springs Endodontics | Q3: https://www.loopnet.com/Listing/1049-Willa-Springs-Dr-Winter-Springs-FL/28712543/ | R3: https://www.google.com/maps/search/?api=1&query=1049+Willa+Springs+Dr+Seminole+FL | S3: Mixed use; figure out which unit if possible
A4: 3 | B4: 800 Fern Creek Av N | C4: Orange | D4: 2023/06 | E4: 1100000 | F4: =Table2[[#This Row],[Price]]/Table2[[#This Row],[Tot Ht Area]] -> 250.62657 | G4: 4389 | H4: 4697 | I4: Bk Realty Holding Company LLC | J4: 1956 | K4: 1700 | L4: ORLO1/ | M4: 2229 24 7060 03 010 | N4: Medical | O4: Medium | P4: Ferncreek Professional Center | Q4: https://www.tdscommercialre.com/properties | R4: https://www.google.com/maps/search/800+Fern+Creek+Av+N+Orange+FL
A5: 3 | B5: 1207 Daniels Rd | C5: Orange | D5: 2023/02 | E5: 1800000 | F5: =Table2[[#This Row],[Price]]/Table2[[#This Row],[Tot Ht Area]] -> 179.24716 | G5: 10042 | H5: 10618 | I5: Verax Daniels LLC | J5: 2024 | K5: 1900 | L5: WGC2 | M5: 2227 12 6496 28 002 | N5: Multi-Tenant Medical | O5: High | P5: Medical Office Development (Planned) | Q5: https://www.crexi.com/property-records/1207-DANIELS-WINTER-GARDEN-FL-34787/7098de1c88aa1c1be75e9a881083c5bb742ec848 | R5: https://www.google.com/maps/search/1207+Daniels+Rd,+FL
A6: 3 | B6: 54 Plant St E | C6: Orange | D6: 2025/03 | E6: 3200000 | F6: =Table2[[#This Row],[Price]]/Table2[[#This Row],[Tot Ht Area]] -> 893.85475 | G6: 3580 | H6: 4021 | I6: Anton Rx LLC | J6: 1983 | K6: 1900 | L6: WGC1 | M6: 2227 23 2888 01 040 | N6: Medical | O6: Medium | P6: Anton Rx (Pharmacy) | Q6: https://search.sunbiz.org/Inquiry/corporationsearch/SearchResultDetail?inquirytype=EntityName&directionType=Initial&searchNameOrder=ANTONRX%20L210004523910 | R6: https://www.google.com/maps/search/54+Plant+St+E,+FL | T6: Yes | U6: Extreme | V6: https://vgispublic.ocpafl.org/webmapjs/?pid=272223288801040
A7: 3 | B7: 20 Park Av S | C7: Orange | D7: 2021/06 | E7: 592000 | F7: =Table2[[#This Row],[Price]]/Table2[[#This Row],[Tot Ht Area]] -> 169.14286 | G7: 3500 | H7: 3850 | I7: Spark Office LLC | J7: 1996 | K7: 1700 | L7: APKMUD | M7: 2128 09 1972 02 591 | N7: Medical | O7: High | P7: Medical Buildout (Tenant Unconfirmed) | Q7: https://www.loopnet.com/Listing/20-S-Park-Ave-Apopka-FL/16369407/ | R7: https://www.google.com/maps/search/20+Park+Av+S,+FL
A8: 3 | B8: 404 Orange Blossom Tr W | C8: Orange | D8: 2025/05 | E8: 2000000 | F8: =Table2[[#This Row],[Price]]/Table2[[#This Row],[Tot Ht Area]] -> 351.61744 | G8: 5688 | H8: 5723 | I8: Galvan Victor M | J8: 1986 | K8: 1700 | L8: APKMUD | M8: 2128 09 7544 02 030 | N8: Medical | O8: Medium | P8: South Apopka Medical Office (Vacant/Leasing) | Q8: https://www.loopnet.com/Listing/404-W-Orange-Blossom-Tr-Apopka-FL/28471952/ | R8: https://www.google.com/maps/search/404+Orange+Blossom+Tr+W,+FL
A9: 3 | B9: 566 Ocoee Commerce Pk | C9: Orange | D9: 2025/10 | E9: 100 | F9: =Table2[[#This Row],[Price]]/Table2[[#This Row],[Tot Ht Area]] -> 0.019968051 | G9: 5008 | H9: 5182 | I9: 566 596 Ocoee Commerce Pkwy LLC | J9: 2009 | K9: 1900 | L9: OCOC2 | M9: 2228 29 6143 00 050 | N9: Medical | O9: High | P9: Vacant Medical/Professional Buildout | Q9: https://www.loopnet.com/Listing/566-Ocoee-Commerce-Pky-Ocoee-FL/38309702/ | R9: https://www.google.com/maps/search/566+Ocoee+Commerce+Pk,+FL | T9: Yes
A10: 3 | B10: 2702 Rew Ci | C10: Orange | D10: 2021/11 | E10: 1224900 | F10: =Table2[[#This Row],[Price]]/Table2[[#This Row],[Tot Ht Area]] -> 236.14806 | G10: 5187 | H10: 5571 | I10: Marcast Properties & Management LLC | J10: 2003 | K10: 1900 | L10: OCOI1 | M10: 2228 29 9158 00 020 | N10: Medical | O10: Medium | P10: Vacant Medical/Office Space | Q10: https://www.loopnet.com/Listing/2702-Rew-Cir-Ocoee-FL/20805631/ | R10: https://www.google.com/maps/search/2702+Rew+Ci,+FL
A11: 3 | B11: 5749 Westgate Dr | C11: Orange | D11: 2025/03 | E11: 6850000 | F11: =Table2[[#This Row],[Price]]/Table2[[#This Row],[Tot Ht Area]] -> 155.79158 | G11: 43969 | H11: 47089 | I11: Clarcona Land Development LLC | J11: 2008 | K11: 1800 | L11: ORLAC1 | M11: 2228 36 4949 01 000 | N11: Multi-Tenant Medical | O11: High | P11: Vacant Medical/Wellness Buildout | Q11: https://www.bosshardtrealty.com/listing/O6296860/5749-westgate-drive-orlando-fl-32835/ | R11: https://www.google.com/maps/search/5749+Westgate+Dr,+FL | T11: Yes | U11: Not all medical | V11: https://vgispublic.ocpafl.org/webmapjs/?pid=282236494901000
A12: 3 | B12: 7232 Sand Lake Rd W | C12: Orange | D12: 2025/07 | E12: 7500000 | F12: =Table2[[#This Row],[Price]]/Table2[[#This Row],[Tot Ht Area]] -> 441.82622 | G12: 16975 | H12: 17657 | I12: Andres Health Holdings LLC | J12: 1983 | K12: 1800 | L12: ORGC1 | M12: 2328 35 0000 00 016 | N12: Multi-Tenant Medical | O12: Medium | P12: Andres Health Holdings (Tenant Unconfirmed) | Q12: https://www.loopnet.com/Listing/7232-Sand-Lake-Rd-Orlando-FL/31873125/ | R12: https://www.google.com/maps/search/7232+Sand+Lake+Rd+W,+FL
A13: 3 | B13: 926 Maitland Av N | C13: Orange | D13: 2023/06 | E13: 720000 | F13: =Table2[[#This Row],[Price]]/Table2[[#This Row],[Tot Ht Area]] -> 364.37247 | G13: 1976 | H13: 2087 | I13: Dream Dental Properties LLC | J13: 1957 | K13: 1900 | L13: MTLMX | M13: 2129 25 0000 00 021 | N13: Medical | O13: High | P13: Vacant "Turnkey" Medical Buildout | Q13: https://www.ronsellsthebeach.com/property-search/detail/240/O6341577/926-n-maitland-ave-maitland-fl-32751/ | R13: https://www.google.com/maps/search/926+Maitland+Av+N,+FL
A14: 3 | B14: 2200 Lee Rd | C14: Orange | D14: 2022/03 | E14: 800000 | F14: =Table2[[#This Row],[Price]]/Table2[[#This Row],[Tot Ht Area]] -> 322.58065 | G14: 2480 | H14: 2673 | I14: Aarr Florida Investments LLC | J14: 1976 | K14: 1900 | L14: WPO1 | M14: 2229 02 8004 01 004 | N14: Medical | O14: High | P14: Vacant Medical Buildout (Former Dentist) | Q14: https://www.loopnet.com/Listing/2200-Lee-Rd-Winter-Park-FL/24836441/ | R14: https://www.google.com/maps/search/2200+Lee+Rd,+FL
A15: 3 | B15: 2306 Lee Rd | C15: Orange | D15: 2022/04 | E15: 100 | F15: =Table2[[#This Row],[Price]]/Table2[[#This Row],[Tot Ht Area]] -> 0.044326241 | G15: 2256 | H15: 2289 | I15: Naseem Bano Latif Revocable Trust & Latif Mohammad A | J15: 1984 | K15: 1900 | L15: WPO1 | M15: 2229 02 8008 01 181 | N15: Medical | O15: High | P15: Vacant Medical Buildout (Plumbed Exam Rooms) | Q15: Used to be Longwood Internal Medicine | R15: https://www.google.com/maps/search/2306+Lee+Rd,+FL | T15: Yes
A16: 3 | B16: 1010 Arthur Av | C16: Orange | D16: 2022/05 | E16: 925000 | F16: =Table2[[#This Row],[Price]]/Table2[[#This Row],[Tot Ht Area]] -> 262.41135 | G16: 3525 | H16: 3525 | I16: A Swart Properties LLC | J16: 1984 | K16: 1900 | L16: ORLMU1 | M16: 2229 10 8828 04 150 | N16: Medical | O16: High | P16: The Spa Orlando (Massage & Wellness) | Q16: Used to be https://www.tolbirth.com/ | R16: https://www.google.com/maps/search/1010+Arthur+Av+Orange+FL
A17: 3 | B17: 205 Eola Dr S | C17: Orange | D17: 2020/02 | E17: 3325000 | F17: =Table2[[#This Row],[Price]]/Table2[[#This Row],[Tot Ht Area]] -> 433.9598 | G17: 7662 | H17: 8163 | I17: Whitestone Legacy LLC | J17: 1945 | K17: 1700 | L17: ORLPD/ | M17: 2229 25 9320 01 060 | N17: Medical | O17: Medium | P17: Vacant "Office/Medical" for Sale | Q17: https://www.crexi.com/properties/2285495/florida-8000-sf-office-for-sale-in-downtown-orlando | R17: https://www.google.com/maps/search/205+Eola+Dr+S+Orange+FL
A18: 3 | B18: 1701 1st St W | C18: Seminole | D18: 2024/10 | E18: 940000 | F18: =Table2[[#This Row],[Price]]/Table2[[#This Row],[Tot Ht Area]] -> 109.98011 | G18: 8547 | H18: 8547 | I18: 1701 West First Street LLC | J18: 2005 | K18: 19 | M18: 1930 25 5AG 0320 0000 | N18: Medical | O18: Medium | P18: Vacant "2nd Gen Medical" for Lease (used to be DaVita Dialysis) | Q18: https://www.loopnet.com/Listing/1701-W-1st-St-Sanford-FL/28259426/ | R18: https://www.google.com/maps?q=1701+1st+St+W+Seminole,+FL
A19: 3 | B19: 902 25th St W | C19: Seminole | D19: 2025/07 | E19: 100 | F19: =Table2[[#This Row],[Price]]/Table2[[#This Row],[Tot Ht Area]] -> 0.047778309 | G19: 2093 | H19: 2093 | I19: Honu Molar Building LLC | J19: 1978 | K19: 19 | M19: 1930 36 524 0900 0010 | N19: Medical | O19: Medium | P19: Dr. Randall C. Brown, DMD | Q19: https://search.sunbiz.org/Inquiry/CorporationSearch/ByName | R19: https://maps.google.com/?cid=1507629469026860988&g_mp=Cidnb29nbGUubWFwcy5wbGFjZXMudjEuUGxhY2VzLlNlYXJjaFRleHQ | T19: Yes
A20: 3 | B20: 795 Primera Blvd | C20: Seminole | D20: 2020/12 | E20: 2375000 | F20: =Table2[[#This Row],[Price]]/Table2[[#This Row],[Tot Ht Area]] -> 220.33584 | G20: 10779 | H20: 10779 | I20: Medwins Realty LLC | J20: 2007 | K20: 1905 | M20: 2030 07 522 0600 0000 | N20: Multi-Tenant Medical | O20: Medium | Q20: https://www.loopnet.com/Listing/795-Primera-Blvd-Lake-Mary-FL/15799815/ | R20: https://www.google.com/maps?q=795+Primera+Blvd+Seminole,+FL
A21: 3 | B21: 261 Airport Blvd E | C21: Seminole | D21: 2021/04 | E21: 600000 | F21: =Table2[[#This Row],[Price]]/Table2[[#This Row],[Tot Ht Area]] -> 173.81228 | G21: 3452 | H21: 3452 | I21: Shephard Max Properties LLC | J21: 1980 | K21: 19 | M21: 2030 12 300 012H 0000 | N21: Medical | O21: Medium | P21: Vacant Medical Office (For Sale) | Q21: https://www.realty.com/commercial-listings/361178951/261-E-Airport-Boulevard-Sanford-FL-32773 | R21: https://www.google.com/maps?q=261+Airport+Blvd+E+Seminole,+FL
A22: 3 | B22: 32032 Burleigh Blvd W | C22: Lake | D22: 2020/09 | E22: 670000 | F22: =Table2[[#This Row],[Price]]/Table2[[#This Row],[Tot Ht Area]] -> 135.40825 | G22: 4948 | H22: 5250 | I22: Burleigh Getting Started LLC | J22: 1977 | K22: 1900 | M22: 1926 29 0700 000 00002 | N22: Medical | O22: Medium | P22: Vacant Dental Office (Built-out) | Q22: https://www.loopnet.com/Listing/320-W-Burleigh-Blvd-Tavares-FL/18724440/ | R22: https://www.google.com/maps/search/32032+Burleigh+Blvd+W+Tavares+FL
A23: 3 | B23: 6909 Old Hwy 441 | C23: Orange | D23: 2021/07 | E23: 3000000 | F23: =Table2[[#This Row],[Price]]/Table2[[#This Row],[Tot Ht Area]] -> 62.138818 | G23: 48279 | H23: 55177 | I23: Mount Fpl LLC | J23: 2008 | K23: 1900 | L23: ORGPD | M23: 2027 05 3095 01 000 | N23: Multi-Tenant Medical | O23: High | P23: Multi-Tenant (Endocrinology / Dialysis) | Q23: https://www.cityfeet.com/cont/listing/6909-old-highway-441-mount-dora-fl-32757/cs23886257 | R23: https://www.google.com/maps/search/6909+Old+Hwy+441,+FL | T23: Yes | U23: Multi tenant sale/ bad Cap Rate? | V23: https://vgispublic.ocpafl.org/webmapjs/?pid=272005309501000
A24: 3 | B24: 1200 Plant St E | C24: Orange | D24: 2022/04 | E24: 100 | F24: =Table2[[#This Row],[Price]]/Table2[[#This Row],[Tot Ht Area]] -> 0.0045390586 | G24: 22031 | H24: 26965 | I24: Hwo Holdings LLC | J24: 2020 | K24: 1800 | L24: WGCAPU | M24: 2227 12 6496 04 001 | N24: Medical | O24: High | P24: Healthy West Orange / Community Hub | Q24: https://www.cwgdn.com/666/Central-Florida-Resources | R24: https://www.google.com/maps/search/1200+Plant+St+E,+FL | T24: Yes
A25: 3 | B25: 14835 Colonial Dr W | C25: Orange | D25: 2021/05 | E25: 344600 | F25: =Table2[[#This Row],[Price]]/Table2[[#This Row],[Tot Ht Area]] -> 117.37057 | G25: 2936 | H25: 3048 | I25: Life Conduit LLC | J25: 2021 | K25: 1900 | L25: WGC2 | M25: 2227 22 7670 03 000 | N25: Medical | O25: High | P25: Wholistic Dental Care | Q25: https://search.sunbiz.org/Inquiry/corporationsearch/SearchResultDetail?inquirytype=EntityName&directionType=Initial&searchNameOrder=WHOLISTICDENTALCAREWINTERGARDE%20L210000916830 | R25: https://www.google.com/maps/search/14835+Colonial+Dr+W,+FL
A26: 3 | B26: 741 Dillard St S | C26: Orange | D26: 2021/03 | E26: 900000 | F26: =Table2[[#This Row],[Price]]/Table2[[#This Row],[Tot Ht Area]] -> 152.54237 | G26: 5900 | H26: 6304 | I26: 741 South Dillard LLC | J26: 1970 | K26: 1900 | L26: WGC2 | M26: 2227 23 6504 07 072 | N26: Medical | O26: High | P26: Ability Rehabilitation (Physical Therapy) | Q26: https://abilityrehabilitation.com/winter-garden-clinic/ | R26: https://www.google.com/maps/search/741+Dillard+St+S,+FL
A27: 3 | B27: 950 Dillard St S | C27: Orange | D27: 2021/10 | E27: 1365500 | F27: =Table2[[#This Row],[Price]]/Table2[[#This Row],[Tot Ht Area]] -> 410.30649 | G27: 3328 | H27: 4909 | I27: 950 Dillard LLC | J27: 1998 | K27: 1700 | L27: WGC2 | M27: 2227 23 7824 00 260 | N27: Medical | O27: High | P27: Gentiva Hospice | Q27: https://allianceforcareathome.org/nahc_provider/gentiva-hospice-winter-garden/ | R27: https://www.google.com/maps/search/950+Dillard+St+S,+FL
A28: 3 | B28: 12323 Colonial Dr W | C28: Orange | D28: 2021/02 | E28: 1900000 | F28: =Table2[[#This Row],[Price]]/Table2[[#This Row],[Tot Ht Area]] -> 82.691387 | G28: 22977 | H28: 25035 | I28: Verax Wg LLC | J28: 2022 | K28: 1900 | L28: WGPCD | M28: 2227 24 6747 04 000 | N28: Multi-Tenant Medical | O28: High | P28: Winter Garden ObGyn / ENT & Plastic Surgery | Q28: https://wgobgyn.com/ | R28: https://www.google.com/maps/search/12323+Colonial+Dr+W,+FL | T28: Yes | U28: You guys now here? | V28: https://vgispublic.ocpafl.org/webmapjs/?pid=272224674704000
A29: 3 | B29: 12200 Colonial Dr W | C29: Orange | D29: 2021/11 | E29: 7600000 | F29: =Table2[[#This Row],[Price]]/Table2[[#This Row],[Tot Ht Area]] -> 246.90556 | G29: 30781 | H29: 32341 | I29: 12200 Colonial LLC | J29: 2000 | K29: 1800 | L29: WGC2 | M29: 2227 25 0000 00 035 | N29: Multi-Tenant Medical | O29: High | P29: Oral Surgery Center Of West Orlando | Q29: https://www.carecredit.com/doctor-locator/winter-garden-fl/oral-surgery-center-of-west-orlando-pqr222/ | R29: https://www.google.com/maps/search/12200+Colonial+Dr+W,+FL
A30: 3 | B30: 15650 Colonial Dr W | C30: Orange | D30: 2021/03 | E30: 1725000 | F30: =Table2[[#This Row],[Price]]/Table2[[#This Row],[Tot Ht Area]] -> 347.78226 | G30: 4960 | H30: 5608 | I30: Harmony Dental Holdings LLC | J30: 2020 | K30: 1900 | L30: WGC2 | M30: 2227 28 0000 00 001 | N30: Medical | O30: High | P30: Harmony Dental Care / Oakland Pediatric Dentistry | Q30: https://www.carecredit.com/doctor-locator/winter-garden-fl/harmony-dental-care-633hqp/ | R30: https://www.google.com/maps/search/15650+Colonial+Dr+W,+FL
A31: 3 | B31: 5802 Citrus Village Bl | C31: Orange | D31: 2022/11 | E31: 900000 | F31: =Table2[[#This Row],[Price]]/Table2[[#This Row],[Tot Ht Area]] -> 253.52113 | G31: 3550 | H31: 3733 | I31: Med Consult One Properties LLC | J31: 2024 | K31: 1900 | L31: ORGPD | M31: 2327 20 2717 02 000 | N31: Medical | O31: High | P31: Horizons OBGYN & Aesthetics | Q31: https://biz.wochamber.com/list/member/horizons-obgyn-30930 | R31: https://www.google.com/maps/search/5802+Citrus+Village+Bl,+FL
A32: 3 | B32: 11625 Lachlan Ln | C32: Orange | D32: 2025/06 | E32: 3473802 | F32: =Table2[[#This Row],[Price]]/Table2[[#This Row],[Tot Ht Area]] -> 915.12171 | G32: 3796 | H32: 3922 | I32: Cl Westside Shoppes Fl LLC | J32: 2017 | K32: 1900 | L32: ORGPD | M32: 2327 25 5839 02 000 | N32: Medical | O32: High | P32: Dental Care at Westside Shoppes | Q32: https://dentalcareatwestsideshoppes.com/ | R32: https://www.google.com/maps/search/11625+Lachlan+Ln,+FL | T32: Yes | U32: Extreme | V32: https://vgispublic.ocpafl.org/webmapjs/?pid=272325583902000
A33: 3 | B33: 1112 Rock Springs Rd | C33: Orange | D33: 2020/12 | E33: 100 | F33: =Table2[[#This Row],[Price]]/Table2[[#This Row],[Tot Ht Area]] -> 0.036363636 | G33: 2750 | H33: 2876 | I33: Pta Properties LLC | J33: 2012 | K33: 1900 | L33: APKO | M33: 2028 33 0000 00 067 | N33: Medical | O33: High | P33: Arbor Dentistry | Q33: https://fun4seminolekids.com/Health-Resources/Family-Dental-Practices/Arbor-Dentistry/View-details | R33: https://www.google.com/maps/search/1112+Rock+Springs+Rd,+FL | T33: Yes
A34: 3 | B34: 450 Errol Pk | C34: Orange | D34: 2024/09 | E34: 448100 | F34: =Table2[[#This Row],[Price]]/Table2[[#This Row],[Tot Ht Area]] -> 130.79393 | G34: 3426 | H34: 3590 | I34: 6Gamms LLC | J34: 1981 | K34: 1900 | L34: APKCC | M34: 2128 05 0000 00 016 | N34: Medical | O34: High | P34: A Soft Touch in Family Dental Care | Q34: https://www.patientconnect365.com/Dentists/Florida/Apopka/32712/A_Soft_Touch_in_Family_Dental_Care__Dr_John_Gammichia_kvo8lh | R34: https://www.google.com/maps/search/450+Errol+Pk,+FL
A35: 3 | B35: 2115 Orange Blossom Tr W | C35: Orange | D35: 2024/05 | E35: 3500000 | F35: =Table2[[#This Row],[Price]]/Table2[[#This Row],[Tot Ht Area]] -> 591.01655 | G35: 5922 | H35: 6039 | I35: Fla Land Holdings Three LLC | J35: 2023 | K35: 1900 | L35: ORGC1 | M35: 2128 06 0000 00 047 | N35: Hospitals | O35: High | P35: Sanitas Medical Center | Q35: https://www.mysanitas.com/en/fl/sanitas-apopka | R35: https://www.google.com/maps/search/2115+Orange+Blossom+Tr+W,+FL | T35: Yes | U35: Hospital, but too small to go under our "large buildings category" | V35: https://vgispublic.ocpafl.org/webmapjs/?pid=282106000000047
A36: 3 | B36: 108 Park Av S | C36: Orange | D36: 2023/10 | E36: 475000 | F36: =Table2[[#This Row],[Price]]/Table2[[#This Row],[Tot Ht Area]] -> 102.81385 | G36: 4620 | H36: 4745 | I36: Dada Eyecare Holdings LLC | J36: 2024 | K36: 1900 | L36: APKMUD | M36: 2128 09 0196 20 063 | N36: Medical | O36: High | P36: Essential Eye Care & Optical | Q36: https://www.essentialeyecareoptical.com/hours-location/ | R36: https://www.google.com/maps/search/108+Park+Av+S,+FL
A37: 3 | B37: 416 Main St E | C37: Orange | D37: 2024/05 | E37: 585000 | F37: =Table2[[#This Row],[Price]]/Table2[[#This Row],[Tot Ht Area]] -> 127.45098 | G37: 4590 | H37: 5490 | I37: Collins Construction Consulting Hold | J37: 1966 | K37: 1700 | L37: APKMUD | M37: 2128 10 0000 00 051 | N37: Medical | O37: High | P37: Owner-Occupied Dental Office / Beauty Salon | Q37: https://www.kwsouthshore.com/listings/listing/416-e-main-st-apopka-fl--O6171656/ | R37: https://www.google.com/maps/search/416+Main+St+E,+FL
A38: 3 | B38: 125 Park Av S | C38: Orange | D38: 2020/07 | E38: 100 | F38: =Table2[[#This Row],[Price]]/Table2[[#This Row],[Tot Ht Area]] -> 0.031162356 | G38: 3209 | H38: 3283 | I38: Dean A Behner And Ingrid J Behner Re Dean Allen Behner Trustee | J38: 1960 | K38: 1900 | L38: APKMUD | M38: 2128 10 0198 31 740 | N38: Medical | O38: High | P38: WellMed at Apopka | Q38: https://www.tenantbase.com/us/building/217796 | R38: https://www.google.com/maps/search/125+Park+Av+S,+FL | T38: Yes
A39: 3 | B39: 175 Main St E | C39: Orange | D39: 2023/04 | E39: 2650000 | F39: =Table2[[#This Row],[Price]]/Table2[[#This Row],[Tot Ht Area]] -> 201.67428 | G39: 13140 | H39: 14276 | I39: Jareag 175 LLC | J39: 2006 | K39: 1800 | L39: APKMUD | M39: 2128 10 8643 00 030 | N39: Multi-Tenant Medical | O39: High | P39: Gentry Building | Q39: https://www.loopnet.com/Listing/175-E-Main-St-Apopka-FL/31346793/ | R39: https://www.google.com/maps/search/175+Main+St+E,+FL
A40: 3 | B40: 2605 Ocoee Apopka Rd | C40: Orange | D40: 2023/05 | E40: 1140000 | F40: =Table2[[#This Row],[Price]]/Table2[[#This Row],[Tot Ht Area]] -> 276.90066 | G40: 4117 | H40: 5455 | I40: Y&L Holdings LLC | J40: 2009 | K40: 1900 | L40: OCOPUD | M40: 2228 06 2856 01 000 | N40: Medical | O40: High | P40: Elegantly Dental | Q40: https://www.elegantlydental.com/ocoee-fl/ | R40: https://www.google.com/maps/search/2605+Ocoee+Apopka+Rd,+FL
...

Sheet Medical Sales
A1: *Filter data of exclusively medical office sales and excluding nominal sales ($100)*
A2: VERIFIED VIA HUMAN (1-3 GRADE) | B2: Prpty Addr | C2: County | D2: Date Trnsfr | E2: Price | F2: $/SF | G2: Tot Ht Area | H2: Total Area | I2: Grantee | J2: Yr Built 1 | K2: Use Code | L2: Zoning | M2: Parcel ID | N2: Verdict | O2: Confidence | P2: Current Tenant | Q2: Evidence Link | R2: Google Map Link | S2: Evidence P2. | T2: Building Age | U2: Outlier | V2: Year | W2: Size Bracket
A3: 3 | B3: 1605 Fairbanks Av W | C3: Orange | D3: 2021/12 | E3: 5000000 | F3: =E3/G3 -> 405.28492 | G3: 12337 | H3: 14132 | I3: AdventHealth Medical Group Cardiology MEDICAL CENTER | J3: 2005 | K3: 1900 | L3: WPO1 | M3: 2229 12 0000 00 001 | N3: Hospitals | O3: High | P3: **AdventHealth Medical Group Cardiology** MEDICAL CENTER | Q3: https://www.adventhealth.com/find-doctor/doctor/basiem-barsoum-md-1104099456 | R3: https://www.google.com/maps/search/1605+Fairbanks+Av+W+Orange+FL | T3: =IF(OR(J3="",D3=""),"Unknown",IF(LEFT(D3,4)*1-J3*1<=10,"New",IF(LEFT(D3,4)*1-J3*1<=25,"Normal","Old"))) -> Normal | U3: Yes | V3: =LEFT(D3,4)*1 -> 2021 | W3: 4. 10 - 20K SF
A4: 3 | B4: 16831 US Highway 441 | C4: Lake | D4: 2021/12 | E4: 3060000 | F4: =E4/G4 -> 278.71391 | G4: 10979 | H4: 12986 | I4: HCA Florida Eustis Emergency Room MEDICAL CENTER | J4: 2023 | K4: 1900 | M4: 1926 23 0004 000 02900 | N4: Hospitals | O4: High | P4: **HCA Florida Eustis Emergency Room** MEDICAL CENTER | Q4: https://www.hcafloridahealthcare.com/locations/mount-dora-emergency | R4: https://www.google.com/maps?q=16831+US+Highway+441+Lake,+FL | T4: =IF(OR(J4="",D4=""),"Unknown",IF(LEFT(D4,4)*1-J4*1<=10,"New",IF(LEFT(D4,4)*1-J4*1<=25,"Normal","Old"))) -> New | U4: Yes | V4: =LEFT(D4,4)*1 -> 2021 | W4: 4. 10 - 20K SF
A5: 3 | B5: 1724 Mills Av N | C5: Orange | D5: 2025/04 | E5: 33444697 | F5: =E5/G5 -> 478.33489 | G5: 69919 | H5: 77729 | I5: Adventist Health System/Sunbelt Inc | J5: 2024 | K5: 1900 | L5: ORLPD/ | M5: 2229 24 8833 02 000 | N5: Hospitals | O5: High | P5: **Charter Research (Clinical Trials)** MEDICAL CENTER | Q5: https://seamless.ai/b/charter-research-6612681 | R5: https://www.google.com/maps/search/1724+Mills+Av+N+Orange+FL | T5: =IF(OR(J5="",D5=""),"Unknown",IF(LEFT(D5,4)*1-J5*1<=10,"New",IF(LEFT(D5,4)*1-J5*1<=25,"Normal","Old"))) -> New | V5: =LEFT(D5,4)*1 -> 2025 | W5: 5. 20K+ SF
A6: 3 | B6: 2909 Orange Av N | C6: Orange | D6: 2021/06 | E6: 10221900 | F6: =E6/G6 -> 651.90689 | G6: 15680 | H6: 20440 | I6: Adventist Health System/Sunbelt Inc Attn: Adventhealth Accounting Dept | J6: 1958 | K6: 1900 | L6: ORLMU1 | M6: 2229 13 2784 02 030 | N6: Hospitals | O6: High | P6: Orlando Medical Dental Center MEDICAL CENTER | Q6: https://www.adventhealth.com/ | R6: https://www.google.com/maps/search/2909+Orange+Av+N+Orange+FL | T6: =IF(OR(J6="",D6=""),"Unknown",IF(LEFT(D6,4)*1-J6*1<=10,"New",IF(LEFT(D6,4)*1-J6*1<=25,"Normal","Old"))) -> Old | U6: Yes | V6: =LEFT(D6,4)*1 -> 2021 | W6: 4. 10 - 20K SF
A7: 3 | B7: 3200 Citrus Tower Blvd | C7: Lake | D7: 2020/07 | E7: 1340800 | F7: =E7/G7 -> 111.71471 | G7: 12002 | H7: 12360 | I7: Clermont VA Clinic (Veterans Affairs) MEDICAL CENTER | J7: 2021 | K7: 1900 | M7: 2326 05 0050 000 01300 | N7: Hospitals | O7: High | P7: **Clermont VA Clinic (Veterans Affairs)** MEDICAL CENTER | Q7: https://www.va.gov/orlando-health-care/locations/clermont-va-clinic/ | R7: https://www.google.com/maps/search/?api=1&query=3200+Citrus+Tower+Blvd+Lake+FL | T7: =IF(OR(J7="",D7=""),"Unknown",IF(LEFT(D7,4)*1-J7*1<=10,"New",IF(LEFT(D7,4)*1-J7*1<=25,"Normal","Old"))) -> New | U7: Yes | V7: =LEFT(D7,4)*1 -> 2020 | W7: 4. 10 - 20K SF
A8: 3 | B8: 3480 Polynesian Isle Blvd | C8: Osceola | D8: 2025/04 | E8: 5150000 | F8: =E8/G8 -> 412.66026 | G8: 12480 | H8: 12720 | I8: Vitalis Mob Kissimmee LLC | J8: 2020 | K8: 1911 | L8: OPD | M8: 2528 02 5035 0001 0017 | N8: Hospitals | O8: High | P8: **Florida Lung, Asthma & Sleep Specialists** MEDICAL CENTER | Q8: https://floridalungdoctors.com/polynesian-office/ | R8: https://www.google.com/maps/search/3480+Polynesian+Isle+Blvd+Osceola+FL | T8: =IF(OR(J8="",D8=""),"Unknown",IF(LEFT(D8,4)*1-J8*1<=10,"New",IF(LEFT(D8,4)*1-J8*1<=25,"Normal","Old"))) -> New | U8: Yes | V8: =LEFT(D8,4)*1 -> 2025 | W8: 4. 10 - 20K SF
A9: 3 | B9: 454 Rinehart Rd | C9: Seminole | D9: 2023/10 | E9: 3889000 | F9: =E9/G9 -> 136.42742 | G9: 28506 | H9: 28506 | I9: Orlandohealth Inc | J9: 2024 | K9: 1906 | M9: 2030 06 525 0000 00B0 | N9: Hospitals | O9: High | P9: Orlando Health Jewett Orthopedic Institute MEDICAL CENTER | Q9: https://www.orlandohealth.com/locations/orlando-health-jewett-orthopedic-institute-lake-mary-rinehart | R9: https://www.google.com/maps?q=454+Rinehart+Rd+Seminole,+FL | T9: =IF(OR(J9="",D9=""),"Unknown",IF(LEFT(D9,4)*1-J9*1<=10,"New",IF(LEFT(D9,4)*1-J9*1<=25,"Normal","Old"))) -> New | V9: =LEFT(D9,4)*1 -> 2023 | W9: 5. 20K+ SF
A10: 3 | B10: 658 Oviedo Medical Dr | C10: Seminole | D10: 2024/12 | E10: 9998200 | F10: =E10/G10 -> 587.19681 | G10: 17027 | H10: 17027 | I10: Mmof IV Mid Fl Portfolio LLC C/O Ryan LLC | J10: 2017 | K10: 19 | M10: 2131 16 5CA 0000 120A | N10: Hospitals | O10: High | P10: Hematology and Oncology MEDICAL CENTER | Q10: https://www.orlandohealth.com/physician-finder/alan-r-forbes-md | R10: https://www.google.com/maps/search/?api=1&query=658+Oviedo+Medical+Dr+Seminole+FL | T10: =IF(OR(J10="",D10=""),"Unknown",IF(LEFT(D10,4)*1-J10*1<=10,"New",IF(LEFT(D10,4)*1-J10*1<=25,"Normal","Old"))) -> New | U10: Yes | V10: =LEFT(D10,4)*1 -> 2024 | W10: 4. 10 - 20K SF
A11: 3 | B11: 750 Orienta Ave | C11: Seminole | D11: 2020/04 | E11: 550000 | F11: =E11/G11 -> 45.304778 | G11: 12140 | H11: 12140 | I11: Florida Cancer Specialists MEDICAL CENTER | J11: 2023 | K11: 19 | M11: 2129 12 5BE 0000 4660 | N11: Hospitals | O11: High | P11: **Florida Cancer Specialists** MEDICAL CENTER | Q11: https://flcancer.com/location/altamonte/ | R11: https://www.google.com/maps/search/?api=1&query=750+Orienta+Ave+Seminole+FL | T11: =IF(OR(J11="",D11=""),"Unknown",IF(LEFT(D11,4)*1-J11*1<=10,"New",IF(LEFT(D11,4)*1-J11*1<=25,"Normal","Old"))) -> New | V11: =LEFT(D11,4)*1 -> 2020 | W11: 4. 10 - 20K SF
A12: 3 | B12: 9401 Summit Centre Wa | C12: Orange | D12: 2021/10 | E12: 15500000 | F12: =E12/G12 -> 1500.3388 | G12: 10331 | H12: 12626 | I12: HCA Florida Maitland Emergency (Freestanding ER) MEDICAL CENTER | J12: 2024 | K12: 1900 | L12: MTLPD | M12: 2129 28 5499 03 000 | N12: Hospitals | O12: High | P12: **HCA Florida Maitland Emergency (Freestanding ER)** MEDICAL CENTER | Q12: https://www.hcafloridahealthcare.com/locations/maitland-emergency | R12: https://www.google.com/maps/search/9401+Summit+Centre+Wa,+FL | T12: =IF(OR(J12="",D12=""),"Unknown",IF(LEFT(D12,4)*1-J12*1<=10,"New",IF(LEFT(D12,4)*1-J12*1<=25,"Normal","Old"))) -> New | U12: Yes | V12: =LEFT(D12,4)*1 -> 2021 | W12: 4. 10 - 20K SF
A13: 3 | B13: 100 Waymont Ct | C13: Seminole | D13: 2022/11 | E13: 4100000 | F13: =E13/G13 -> 227.77778 | G13: 18000 | H13: 18000 | I13: AdventHealth Sports Medicine & Rehab | J13: 1997 | K13: 19 | M13: 2030 17 300 0140 0000 | N13: Medical | O13: High | P13: **AdventHealth Sports Medicine & Rehab** | Q13: https://www.adventhealth.com/locations/adventhealth-sports-med-and-rehab-lake-mary | R13: https://www.google.com/maps?q=100+Waymont+Ct+Seminole,+FL | T13: =IF(OR(J13="",D13=""),"Unknown",IF(LEFT(D13,4)*1-J13*1<=10,"New",IF(LEFT(D13,4)*1-J13*1<=25,"Normal","Old"))) -> Normal | U13: Yes | V13: =LEFT(D13,4)*1 -> 2022 | W13: 4. 10 - 20K SF
A14: 3 | B14: 1000 E Irlo Bronson Memorial | C14: Osceola | D14: 2021/01 | E14: 3552600 | F14: =E14/G14 -> 466.95584 | G14: 7608 | H14: 8124 | I14: MedExpress Urgent Care (Optum) MEDICAL CENTER | J14: 2020 | K14: 1911 | L14: SPUD | M14: 2631 07 0212 0001 0010 | N14: Hospitals | O14: High | P14: MedExpress Urgent Care (Optum) MEDICAL CENTER | Q14: https://www.optum.com/en/ | R14: https://www.google.com/maps?q=1000+E+Irlo+Bronson+Memorial+Osceola,+FL | T14: =IF(OR(J14="",D14=""),"Unknown",IF(LEFT(D14,4)*1-J14*1<=10,"New",IF(LEFT(D14,4)*1-J14*1<=25,"Normal","Old"))) -> New | U14: Yes | V14: =LEFT(D14,4)*1 -> 2021 | W14: 3. 6 - 10K SF
A15: 3 | B15: 1001 W Cherry St | C15: Osceola | D15: 2021/12 | E15: 1010000 | F15: =E15/G15 -> 175.49957 | G15: 5755 | H15: 5959 | I15: Acaba Properties LLC | J15: 2003 | K15: 1911 | L15: KHC | M15: 2529 21 1212 0001 0010 | N15: Medical | O15: High | P15: Sunshine Family Medical and Wellness | Q15: https://sunshinefmwc.com/ | R15: https://www.google.com/maps/search/1001+W+Cherry+St+Osceola+FL | T15: =IF(OR(J15="",D15=""),"Unknown",IF(LEFT(D15,4)*1-J15*1<=10,"New",IF(LEFT(D15,4)*1-J15*1<=25,"Normal","Old"))) -> Normal | U15: Yes | V15: =LEFT(D15,4)*1 -> 2021 | W15: 2. 3 - 6K SF
A16: 3 | B16: 101 Bellagio Cir | C16: Seminole | D16: 2020/08 | E16: 1340000 | F16: =E16/G16 -> 517.97449 | G16: 2587 | H16: 2587 | I16: American Hospitality Assn Inc | J16: 2007 | K16: 1905 | M16: 1930 28 520 0000 0330 | N16: Medical | O16: High | P16: Coastal Mental Health Center (Condo) | Q16: https://coastalmhc.com/ | R16: https://maps.google.com/?cid=8827082157455925323&g_mp=Cidnb29nbGUubWFwcy5wbGFjZXMudjEuUGxhY2VzLlNlYXJjaFRleHQ | T16: =IF(OR(J16="",D16=""),"Unknown",IF(LEFT(D16,4)*1-J16*1<=10,"New",IF(LEFT(D16,4)*1-J16*1<=25,"Normal","Old"))) -> Normal | V16: =LEFT(D16,4)*1 -> 2020 | W16: 1. < 3K SF
A17: 3 | B17: 1010 Arthur Av | C17: Orange | D17: 2022/05 | E17: 925000 | F17: =E17/G17 -> 262.41135 | G17: 3525 | H17: 3525 | I17: The Spa Orlando (Massage & Wellness) | J17: 1984 | K17: 1900 | L17: ORLMU1 | M17: 2229 10 8828 04 150 | N17: Medical | O17: High | P17: **The Spa Orlando (Massage & Wellness)** | Q17: Used to be https://www.tolbirth.com/ | R17: https://www.google.com/maps/search/5749+Westgate+Dr,+FL+R13 | T17: =IF(OR(J17="",D17=""),"Unknown",IF(LEFT(D17,4)*1-J17*1<=10,"New",IF(LEFT(D17,4)*1-J17*1<=25,"Normal","Old"))) -> Old | U17: Yes | V17: =LEFT(D17,4)*1 -> 2022 | W17: 2. 3 - 6K SF
A18: 3 | B18: 1010 W Oak St | C18: Osceola | D18: 2024/06 | E18: 2002800 | F18: =E18/G18 -> 302.1726 | G18: 6628 | H18: 6628 | I18: Cream Rises To The Top Real Estate Holdings LLC | J18: 2010 | K18: 1911 | L18: KB5 | M18: 2529 21 1069 0001 0010 | N18: Medical | O18: High | P18: Medical | Q18: https://www.loopnet.com/Listing/1010-1020-W-Oak-St-Kissimmee-FL/31250163/ | R18: https://www.google.com/maps/search/1010+W+Oak+St+Osceola+FL | T18: =IF(OR(J18="",D18=""),"Unknown",IF(LEFT(D18,4)*1-J18*1<=10,"New",IF(LEFT(D18,4)*1-J18*1<=25,"Normal","Old"))) -> Normal | U18: Yes | V18: =LEFT(D18,4)*1 -> 2024 | W18: 3. 6 - 10K SF
A19: 3 | B19: 1045 N John Young Pkwy | C19: Osceola | D19: 2025/08 | E19: 2310000 | F19: =E19/G19 -> 320.83333 | G19: 7200 | H19: 7200 | I19: Nova Health Medical Group LLC | J19: 1999 | K19: 1911 | L19: KHC | M19: 2529 21 1412 0001 0020 | N19: Medical | O19: High | P19: **Nova Health Medical Group (Primary Care)** | Q19: https://www.loopnet.com/Listing/1045-1085-N-John-Young-Pky-Kissimmee-FL/31094164/ | R19: https://www.google.com/maps/search/1045+N+John+Young+Pkwy+Osceola+FL | S19: investment sale | T19: =IF(OR(J19="",D19=""),"Unknown",IF(LEFT(D19,4)*1-J19*1<=10,"New",IF(LEFT(D19,4)*1-J19*1<=25,"Normal","Old"))) -> Old | U19: Yes | V19: =LEFT(D19,4)*1 -> 2025 | W19: 3. 6 - 10K SF
